[2025-07-22T14:31:46.975+0000] {local_task_job_runner.py:120} INFO - ::group::Pre task execution logs
[2025-07-22T14:31:46.995+0000] {taskinstance.py:2076} INFO - Dependencies all met for dep_context=non-requeueable deps ti=<TaskInstance: flight_data_pipeline.run_spark_job_container scheduled__2025-07-22T14:15:00+00:00 [queued]>
[2025-07-22T14:31:47.000+0000] {taskinstance.py:2076} INFO - Dependencies all met for dep_context=requeueable deps ti=<TaskInstance: flight_data_pipeline.run_spark_job_container scheduled__2025-07-22T14:15:00+00:00 [queued]>
[2025-07-22T14:31:47.001+0000] {taskinstance.py:2306} INFO - Starting attempt 1 of 1
[2025-07-22T14:31:47.012+0000] {taskinstance.py:2330} INFO - Executing <Task(DockerOperator): run_spark_job_container> on 2025-07-22 14:15:00+00:00
[2025-07-22T14:31:47.018+0000] {warnings.py:112} WARNING - /home/***/.local/lib/python3.12/site-packages/***/task/task_runner/standard_task_runner.py:61: DeprecationWarning: This process (pid=1226) is multi-threaded, use of fork() may lead to deadlocks in the child.
  pid = os.fork()

[2025-07-22T14:31:47.020+0000] {standard_task_runner.py:63} INFO - Started process 1228 to run task
[2025-07-22T14:31:47.019+0000] {standard_task_runner.py:90} INFO - Running: ['***', 'tasks', 'run', 'flight_data_pipeline', 'run_spark_job_container', 'scheduled__2025-07-22T14:15:00+00:00', '--job-id', '3', '--raw', '--subdir', 'DAGS_FOLDER/flight_pipeline_dag.py', '--cfg-path', '/tmp/tmpz9o2f68_']
[2025-07-22T14:31:47.021+0000] {standard_task_runner.py:91} INFO - Job 3: Subtask run_spark_job_container
[2025-07-22T14:31:47.067+0000] {task_command.py:426} INFO - Running <TaskInstance: flight_data_pipeline.run_spark_job_container scheduled__2025-07-22T14:15:00+00:00 [running]> on host 73893be039c3
[2025-07-22T14:31:47.139+0000] {taskinstance.py:2648} INFO - Exporting env vars: AIRFLOW_CTX_DAG_OWNER='***' AIRFLOW_CTX_DAG_ID='flight_data_pipeline' AIRFLOW_CTX_TASK_ID='run_spark_job_container' AIRFLOW_CTX_EXECUTION_DATE='2025-07-22T14:15:00+00:00' AIRFLOW_CTX_TRY_NUMBER='1' AIRFLOW_CTX_DAG_RUN_ID='scheduled__2025-07-22T14:15:00+00:00'
[2025-07-22T14:31:47.142+0000] {taskinstance.py:430} INFO - ::endgroup::
[2025-07-22T14:31:47.147+0000] {docker.py:157} ERROR - Failed to establish connection to Docker host unix://var/run/docker.sock: Error while fetching server API version: ('Connection aborted.', FileNotFoundError(2, 'No such file or directory'))
[2025-07-22T14:31:47.147+0000] {taskinstance.py:441} INFO - ::group::Post task execution logs
[2025-07-22T14:31:47.154+0000] {taskinstance.py:2905} ERROR - Task failed with exception
Traceback (most recent call last):
  File "/home/airflow/.local/lib/python3.12/site-packages/airflow/models/taskinstance.py", line 465, in _execute_task
    result = _execute_callable(context=context, **execute_callable_kwargs)
             ^^^^^^^^^^^^^^^^^^^^^^^^^^^^^^^^^^^^^^^^^^^^^^^^^^^^^^^^^^^^^
  File "/home/airflow/.local/lib/python3.12/site-packages/airflow/models/taskinstance.py", line 432, in _execute_callable
    return execute_callable(context=context, **execute_callable_kwargs)
           ^^^^^^^^^^^^^^^^^^^^^^^^^^^^^^^^^^^^^^^^^^^^^^^^^^^^^^^^^^^^
  File "/home/airflow/.local/lib/python3.12/site-packages/airflow/models/baseoperator.py", line 401, in wrapper
    return func(self, *args, **kwargs)
           ^^^^^^^^^^^^^^^^^^^^^^^^^^^
  File "/home/airflow/.local/lib/python3.12/site-packages/airflow/providers/docker/operators/docker.py", line 492, in execute
    if self.force_pull or not self.cli.images(name=self.image):
                              ^^^^^^^^
  File "/home/airflow/.local/lib/python3.12/site-packages/airflow/providers/docker/operators/docker.py", line 362, in cli
    return self.hook.api_client
           ^^^^^^^^^^^^^^^^^^^^
  File "/usr/local/lib/python3.12/functools.py", line 995, in __get__
    val = self.func(instance)
          ^^^^^^^^^^^^^^^^^^^
  File "/home/airflow/.local/lib/python3.12/site-packages/airflow/providers/docker/hooks/docker.py", line 161, in api_client
    raise AirflowException("Failed to establish connection to any given Docker hosts.")
airflow.exceptions.AirflowException: Failed to establish connection to any given Docker hosts.
[2025-07-22T14:31:47.159+0000] {taskinstance.py:1206} INFO - Marking task as FAILED. dag_id=flight_data_pipeline, task_id=run_spark_job_container, run_id=scheduled__2025-07-22T14:15:00+00:00, execution_date=20250722T141500, start_date=20250722T143146, end_date=20250722T143147
[2025-07-22T14:31:47.169+0000] {standard_task_runner.py:110} ERROR - Failed to execute job 3 for task run_spark_job_container (Failed to establish connection to any given Docker hosts.; 1228)
[2025-07-22T14:31:47.194+0000] {local_task_job_runner.py:240} INFO - Task exited with return code 1
[2025-07-22T14:31:47.207+0000] {taskinstance.py:3503} INFO - 0 downstream tasks scheduled from follow-on schedule check
[2025-07-22T14:31:47.209+0000] {local_task_job_runner.py:222} INFO - ::endgroup::
