[2025-07-22T14:46:30.720+0000] {local_task_job_runner.py:120} INFO - ::group::Pre task execution logs
[2025-07-22T14:46:30.741+0000] {taskinstance.py:2076} INFO - Dependencies all met for dep_context=non-requeueable deps ti=<TaskInstance: flight_data_pipeline.run_spark_job_container manual__2025-07-22T14:46:28.856463+00:00 [queued]>
[2025-07-22T14:46:30.747+0000] {taskinstance.py:2076} INFO - Dependencies all met for dep_context=requeueable deps ti=<TaskInstance: flight_data_pipeline.run_spark_job_container manual__2025-07-22T14:46:28.856463+00:00 [queued]>
[2025-07-22T14:46:30.748+0000] {taskinstance.py:2306} INFO - Starting attempt 1 of 1
[2025-07-22T14:46:30.761+0000] {taskinstance.py:2330} INFO - Executing <Task(DockerOperator): run_spark_job_container> on 2025-07-22 14:46:28.856463+00:00
[2025-07-22T14:46:30.767+0000] {warnings.py:112} WARNING - /home/***/.local/lib/python3.12/site-packages/***/task/task_runner/standard_task_runner.py:61: DeprecationWarning: This process (pid=79) is multi-threaded, use of fork() may lead to deadlocks in the child.
  pid = os.fork()

[2025-07-22T14:46:30.769+0000] {standard_task_runner.py:63} INFO - Started process 81 to run task
[2025-07-22T14:46:30.769+0000] {standard_task_runner.py:90} INFO - Running: ['***', 'tasks', 'run', 'flight_data_pipeline', 'run_spark_job_container', 'manual__2025-07-22T14:46:28.856463+00:00', '--job-id', '8', '--raw', '--subdir', 'DAGS_FOLDER/flight_pipeline_dag.py', '--cfg-path', '/tmp/tmpc2jka7m8']
[2025-07-22T14:46:30.770+0000] {standard_task_runner.py:91} INFO - Job 8: Subtask run_spark_job_container
[2025-07-22T14:46:30.812+0000] {task_command.py:426} INFO - Running <TaskInstance: flight_data_pipeline.run_spark_job_container manual__2025-07-22T14:46:28.856463+00:00 [running]> on host 13204a610b7b
[2025-07-22T14:46:30.883+0000] {taskinstance.py:2648} INFO - Exporting env vars: AIRFLOW_CTX_DAG_OWNER='***' AIRFLOW_CTX_DAG_ID='flight_data_pipeline' AIRFLOW_CTX_TASK_ID='run_spark_job_container' AIRFLOW_CTX_EXECUTION_DATE='2025-07-22T14:46:28.856463+00:00' AIRFLOW_CTX_TRY_NUMBER='1' AIRFLOW_CTX_DAG_RUN_ID='manual__2025-07-22T14:46:28.856463+00:00'
[2025-07-22T14:46:30.885+0000] {taskinstance.py:430} INFO - ::endgroup::
[2025-07-22T14:46:30.890+0000] {docker.py:157} ERROR - Failed to establish connection to Docker host unix://var/run/docker.sock: Error while fetching server API version: ('Connection aborted.', PermissionError(13, 'Permission denied'))
[2025-07-22T14:46:30.890+0000] {taskinstance.py:441} INFO - ::group::Post task execution logs
[2025-07-22T14:46:30.899+0000] {taskinstance.py:2905} ERROR - Task failed with exception
Traceback (most recent call last):
  File "/home/airflow/.local/lib/python3.12/site-packages/airflow/models/taskinstance.py", line 465, in _execute_task
    result = _execute_callable(context=context, **execute_callable_kwargs)
             ^^^^^^^^^^^^^^^^^^^^^^^^^^^^^^^^^^^^^^^^^^^^^^^^^^^^^^^^^^^^^
  File "/home/airflow/.local/lib/python3.12/site-packages/airflow/models/taskinstance.py", line 432, in _execute_callable
    return execute_callable(context=context, **execute_callable_kwargs)
           ^^^^^^^^^^^^^^^^^^^^^^^^^^^^^^^^^^^^^^^^^^^^^^^^^^^^^^^^^^^^
  File "/home/airflow/.local/lib/python3.12/site-packages/airflow/models/baseoperator.py", line 401, in wrapper
    return func(self, *args, **kwargs)
           ^^^^^^^^^^^^^^^^^^^^^^^^^^^
  File "/home/airflow/.local/lib/python3.12/site-packages/airflow/providers/docker/operators/docker.py", line 492, in execute
    if self.force_pull or not self.cli.images(name=self.image):
                              ^^^^^^^^
  File "/home/airflow/.local/lib/python3.12/site-packages/airflow/providers/docker/operators/docker.py", line 362, in cli
    return self.hook.api_client
           ^^^^^^^^^^^^^^^^^^^^
  File "/usr/local/lib/python3.12/functools.py", line 995, in __get__
    val = self.func(instance)
          ^^^^^^^^^^^^^^^^^^^
  File "/home/airflow/.local/lib/python3.12/site-packages/airflow/providers/docker/hooks/docker.py", line 161, in api_client
    raise AirflowException("Failed to establish connection to any given Docker hosts.")
airflow.exceptions.AirflowException: Failed to establish connection to any given Docker hosts.
[2025-07-22T14:46:30.903+0000] {taskinstance.py:1206} INFO - Marking task as FAILED. dag_id=flight_data_pipeline, task_id=run_spark_job_container, run_id=manual__2025-07-22T14:46:28.856463+00:00, execution_date=20250722T144628, start_date=20250722T144630, end_date=20250722T144630
[2025-07-22T14:46:30.913+0000] {standard_task_runner.py:110} ERROR - Failed to execute job 8 for task run_spark_job_container (Failed to establish connection to any given Docker hosts.; 81)
[2025-07-22T14:46:30.943+0000] {local_task_job_runner.py:240} INFO - Task exited with return code 1
[2025-07-22T14:46:30.965+0000] {taskinstance.py:3503} INFO - 0 downstream tasks scheduled from follow-on schedule check
[2025-07-22T14:46:30.967+0000] {local_task_job_runner.py:222} INFO - ::endgroup::
