[2025-07-22T17:30:01.825+0000] {local_task_job_runner.py:120} INFO - ::group::Pre task execution logs
[2025-07-22T17:30:01.843+0000] {taskinstance.py:2076} INFO - Dependencies all met for dep_context=non-requeueable deps ti=<TaskInstance: flight_data_pipeline.run_spark_job_container scheduled__2025-07-22T17:15:00+00:00 [queued]>
[2025-07-22T17:30:01.849+0000] {taskinstance.py:2076} INFO - Dependencies all met for dep_context=requeueable deps ti=<TaskInstance: flight_data_pipeline.run_spark_job_container scheduled__2025-07-22T17:15:00+00:00 [queued]>
[2025-07-22T17:30:01.849+0000] {taskinstance.py:2306} INFO - Starting attempt 1 of 1
[2025-07-22T17:30:01.860+0000] {taskinstance.py:2330} INFO - Executing <Task(DockerOperator): run_spark_job_container> on 2025-07-22 17:15:00+00:00
[2025-07-22T17:30:01.865+0000] {warnings.py:112} WARNING - /home/***/.local/lib/python3.12/site-packages/***/task/task_runner/standard_task_runner.py:61: DeprecationWarning: This process (pid=852) is multi-threaded, use of fork() may lead to deadlocks in the child.
  pid = os.fork()

[2025-07-22T17:30:01.867+0000] {standard_task_runner.py:63} INFO - Started process 854 to run task
[2025-07-22T17:30:01.867+0000] {standard_task_runner.py:90} INFO - Running: ['***', 'tasks', 'run', 'flight_data_pipeline', 'run_spark_job_container', 'scheduled__2025-07-22T17:15:00+00:00', '--job-id', '34', '--raw', '--subdir', 'DAGS_FOLDER/flight_pipeline_dag.py', '--cfg-path', '/tmp/tmpn3cx0n73']
[2025-07-22T17:30:01.869+0000] {standard_task_runner.py:91} INFO - Job 34: Subtask run_spark_job_container
[2025-07-22T17:30:01.910+0000] {task_command.py:426} INFO - Running <TaskInstance: flight_data_pipeline.run_spark_job_container scheduled__2025-07-22T17:15:00+00:00 [running]> on host d77a53274a34
[2025-07-22T17:30:01.981+0000] {taskinstance.py:2648} INFO - Exporting env vars: AIRFLOW_CTX_DAG_OWNER='***' AIRFLOW_CTX_DAG_ID='flight_data_pipeline' AIRFLOW_CTX_TASK_ID='run_spark_job_container' AIRFLOW_CTX_EXECUTION_DATE='2025-07-22T17:15:00+00:00' AIRFLOW_CTX_TRY_NUMBER='1' AIRFLOW_CTX_DAG_RUN_ID='scheduled__2025-07-22T17:15:00+00:00'
[2025-07-22T17:30:01.983+0000] {taskinstance.py:430} INFO - ::endgroup::
[2025-07-22T17:30:01.998+0000] {docker.py:493} INFO - Pulling docker image realtime-flight-pipeline/spark-job:0.3
[2025-07-22T17:30:04.063+0000] {taskinstance.py:441} INFO - ::group::Post task execution logs
[2025-07-22T17:30:04.064+0000] {taskinstance.py:2905} ERROR - Task failed with exception
Traceback (most recent call last):
  File "/home/airflow/.local/lib/python3.12/site-packages/docker/api/client.py", line 275, in _raise_for_status
    response.raise_for_status()
  File "/home/airflow/.local/lib/python3.12/site-packages/requests/models.py", line 1021, in raise_for_status
    raise HTTPError(http_error_msg, response=self)
requests.exceptions.HTTPError: 404 Client Error: Not Found for url: http+docker://localhost/v1.49/images/create?tag=0.3&fromImage=realtime-flight-pipeline%2Fspark-job

The above exception was the direct cause of the following exception:

Traceback (most recent call last):
  File "/home/airflow/.local/lib/python3.12/site-packages/airflow/models/taskinstance.py", line 465, in _execute_task
    result = _execute_callable(context=context, **execute_callable_kwargs)
             ^^^^^^^^^^^^^^^^^^^^^^^^^^^^^^^^^^^^^^^^^^^^^^^^^^^^^^^^^^^^^
  File "/home/airflow/.local/lib/python3.12/site-packages/airflow/models/taskinstance.py", line 432, in _execute_callable
    return execute_callable(context=context, **execute_callable_kwargs)
           ^^^^^^^^^^^^^^^^^^^^^^^^^^^^^^^^^^^^^^^^^^^^^^^^^^^^^^^^^^^^
  File "/home/airflow/.local/lib/python3.12/site-packages/airflow/models/baseoperator.py", line 401, in wrapper
    return func(self, *args, **kwargs)
           ^^^^^^^^^^^^^^^^^^^^^^^^^^^
  File "/home/airflow/.local/lib/python3.12/site-packages/airflow/providers/docker/operators/docker.py", line 495, in execute
    for output in self.cli.pull(self.image, stream=True, decode=True):
                  ^^^^^^^^^^^^^^^^^^^^^^^^^^^^^^^^^^^^^^^^^^^^^^^^^^^
  File "/home/airflow/.local/lib/python3.12/site-packages/docker/api/image.py", line 429, in pull
    self._raise_for_status(response)
  File "/home/airflow/.local/lib/python3.12/site-packages/docker/api/client.py", line 277, in _raise_for_status
    raise create_api_error_from_http_exception(e) from e
          ^^^^^^^^^^^^^^^^^^^^^^^^^^^^^^^^^^^^^^^
  File "/home/airflow/.local/lib/python3.12/site-packages/docker/errors.py", line 39, in create_api_error_from_http_exception
    raise cls(e, response=response, explanation=explanation) from e
docker.errors.ImageNotFound: 404 Client Error for http+docker://localhost/v1.49/images/create?tag=0.3&fromImage=realtime-flight-pipeline%2Fspark-job: Not Found ("pull access denied for realtime-flight-pipeline/spark-job, repository does not exist or may require 'docker login': denied: requested access to the resource is denied")
[2025-07-22T17:30:04.072+0000] {taskinstance.py:1206} INFO - Marking task as FAILED. dag_id=flight_data_pipeline, task_id=run_spark_job_container, run_id=scheduled__2025-07-22T17:15:00+00:00, execution_date=20250722T171500, start_date=20250722T173001, end_date=20250722T173004
[2025-07-22T17:30:04.082+0000] {standard_task_runner.py:110} ERROR - Failed to execute job 34 for task run_spark_job_container (404 Client Error for http+docker://localhost/v1.49/images/create?tag=0.3&fromImage=realtime-flight-pipeline%2Fspark-job: Not Found ("pull access denied for realtime-flight-pipeline/spark-job, repository does not exist or may require 'docker login': denied: requested access to the resource is denied"); 854)
[2025-07-22T17:30:04.127+0000] {local_task_job_runner.py:240} INFO - Task exited with return code 1
[2025-07-22T17:30:04.140+0000] {taskinstance.py:3503} INFO - 0 downstream tasks scheduled from follow-on schedule check
[2025-07-22T17:30:04.142+0000] {local_task_job_runner.py:222} INFO - ::endgroup::
