[2025-07-22T14:55:01.862+0000] {local_task_job_runner.py:120} INFO - ::group::Pre task execution logs
[2025-07-22T14:55:01.889+0000] {taskinstance.py:2076} INFO - Dependencies all met for dep_context=non-requeueable deps ti=<TaskInstance: flight_data_pipeline.run_spark_job_container manual__2025-07-22T14:54:58.457259+00:00 [queued]>
[2025-07-22T14:55:01.896+0000] {taskinstance.py:2076} INFO - Dependencies all met for dep_context=requeueable deps ti=<TaskInstance: flight_data_pipeline.run_spark_job_container manual__2025-07-22T14:54:58.457259+00:00 [queued]>
[2025-07-22T14:55:01.897+0000] {taskinstance.py:2306} INFO - Starting attempt 1 of 1
[2025-07-22T14:55:01.910+0000] {taskinstance.py:2330} INFO - Executing <Task(DockerOperator): run_spark_job_container> on 2025-07-22 14:54:58.457259+00:00
[2025-07-22T14:55:01.916+0000] {warnings.py:112} WARNING - /home/***/.local/lib/python3.12/site-packages/***/task/task_runner/standard_task_runner.py:61: DeprecationWarning: This process (pid=68) is multi-threaded, use of fork() may lead to deadlocks in the child.
  pid = os.fork()

[2025-07-22T14:55:01.919+0000] {standard_task_runner.py:63} INFO - Started process 77 to run task
[2025-07-22T14:55:01.917+0000] {standard_task_runner.py:90} INFO - Running: ['***', 'tasks', 'run', 'flight_data_pipeline', 'run_spark_job_container', 'manual__2025-07-22T14:54:58.457259+00:00', '--job-id', '14', '--raw', '--subdir', 'DAGS_FOLDER/flight_pipeline_dag.py', '--cfg-path', '/tmp/tmpur3wl3ug']
[2025-07-22T14:55:01.920+0000] {standard_task_runner.py:91} INFO - Job 14: Subtask run_spark_job_container
[2025-07-22T14:55:01.970+0000] {task_command.py:426} INFO - Running <TaskInstance: flight_data_pipeline.run_spark_job_container manual__2025-07-22T14:54:58.457259+00:00 [running]> on host 5494395689f8
[2025-07-22T14:55:02.043+0000] {taskinstance.py:2648} INFO - Exporting env vars: AIRFLOW_CTX_DAG_OWNER='***' AIRFLOW_CTX_DAG_ID='flight_data_pipeline' AIRFLOW_CTX_TASK_ID='run_spark_job_container' AIRFLOW_CTX_EXECUTION_DATE='2025-07-22T14:54:58.457259+00:00' AIRFLOW_CTX_TRY_NUMBER='1' AIRFLOW_CTX_DAG_RUN_ID='manual__2025-07-22T14:54:58.457259+00:00'
[2025-07-22T14:55:02.044+0000] {taskinstance.py:430} INFO - ::endgroup::
[2025-07-22T14:55:02.047+0000] {docker.py:157} ERROR - Failed to establish connection to Docker host unix://var/run/docker.sock: Error while fetching server API version: ('Connection aborted.', PermissionError(13, 'Permission denied'))
[2025-07-22T14:55:02.048+0000] {taskinstance.py:441} INFO - ::group::Post task execution logs
[2025-07-22T14:55:02.055+0000] {taskinstance.py:2905} ERROR - Task failed with exception
Traceback (most recent call last):
  File "/home/airflow/.local/lib/python3.12/site-packages/airflow/models/taskinstance.py", line 465, in _execute_task
    result = _execute_callable(context=context, **execute_callable_kwargs)
             ^^^^^^^^^^^^^^^^^^^^^^^^^^^^^^^^^^^^^^^^^^^^^^^^^^^^^^^^^^^^^
  File "/home/airflow/.local/lib/python3.12/site-packages/airflow/models/taskinstance.py", line 432, in _execute_callable
    return execute_callable(context=context, **execute_callable_kwargs)
           ^^^^^^^^^^^^^^^^^^^^^^^^^^^^^^^^^^^^^^^^^^^^^^^^^^^^^^^^^^^^
  File "/home/airflow/.local/lib/python3.12/site-packages/airflow/models/baseoperator.py", line 401, in wrapper
    return func(self, *args, **kwargs)
           ^^^^^^^^^^^^^^^^^^^^^^^^^^^
  File "/home/airflow/.local/lib/python3.12/site-packages/airflow/providers/docker/operators/docker.py", line 492, in execute
    if self.force_pull or not self.cli.images(name=self.image):
                              ^^^^^^^^
  File "/home/airflow/.local/lib/python3.12/site-packages/airflow/providers/docker/operators/docker.py", line 362, in cli
    return self.hook.api_client
           ^^^^^^^^^^^^^^^^^^^^
  File "/usr/local/lib/python3.12/functools.py", line 995, in __get__
    val = self.func(instance)
          ^^^^^^^^^^^^^^^^^^^
  File "/home/airflow/.local/lib/python3.12/site-packages/airflow/providers/docker/hooks/docker.py", line 161, in api_client
    raise AirflowException("Failed to establish connection to any given Docker hosts.")
airflow.exceptions.AirflowException: Failed to establish connection to any given Docker hosts.
[2025-07-22T14:55:02.059+0000] {taskinstance.py:1206} INFO - Marking task as FAILED. dag_id=flight_data_pipeline, task_id=run_spark_job_container, run_id=manual__2025-07-22T14:54:58.457259+00:00, execution_date=20250722T145458, start_date=20250722T145501, end_date=20250722T145502
[2025-07-22T14:55:02.069+0000] {standard_task_runner.py:110} ERROR - Failed to execute job 14 for task run_spark_job_container (Failed to establish connection to any given Docker hosts.; 77)
[2025-07-22T14:55:02.093+0000] {local_task_job_runner.py:240} INFO - Task exited with return code 1
[2025-07-22T14:55:02.106+0000] {taskinstance.py:3503} INFO - 0 downstream tasks scheduled from follow-on schedule check
[2025-07-22T14:55:02.108+0000] {local_task_job_runner.py:222} INFO - ::endgroup::
